<?xml version="1.0" ?>
<!-- =================================================================================== -->
<!-- |    This document was autogenerated by xacro from src/four_linkage_demo/demo_common/demo_description/robots/demo_model.urdf.xacro | -->
<!-- |    EDITING THIS FILE BY HAND IS NOT RECOMMENDED                                 | -->
<!-- =================================================================================== -->
<robot name="demo_model">
  <link name="base_link"/>
  <link name="stick_A">
    <visual>
      <origin rpy="0 0 0" xyz="1 0 0"/>
      <geometry>
        <box size="2.0 0.1 0.1"/>
      </geometry>
    </visual>
    <collision>
      <origin rpy="0 0 0" xyz="1 0 0"/>
      <geometry>
        <box size="2. 0.1 0.1"/>
      </geometry>
    </collision>
  </link>
  <joint name="base_link_to_stick_A" type="continuous">
    <axis xyz="0 0 1"/>
    <parent link="base_link"/>
    <child link="stick_A"/>
    <origin rpy="1.57079637 0 0" xyz="0 0 0"/>
  </joint>
  <link name="stick_B">
    <visual>
      <origin rpy="0 0 0" xyz="1 0 0"/>
      <geometry>
        <box size="2.0 0.1 0.1"/>
      </geometry>
    </visual>
    <collision>
      <origin rpy="0 0 0" xyz="1 0 0"/>
      <geometry>
        <box size="2. 0.1 0.1"/>
      </geometry>
    </collision>
  </link>
  <joint name="stick_A_to_stick_B" type="continuous">
    <axis xyz="0 0 1"/>
    <parent link="stick_A"/>
    <child link="stick_B"/>
    <origin rpy="0 0 0" xyz="2 0 0"/>
  </joint>
  <link name="stick_C">
    <visual>
      <origin rpy="0 0 0" xyz="1 0 0"/>
      <geometry>
        <box size="2.0 0.1 0.1"/>
      </geometry>
    </visual>
    <collision>
      <origin rpy="0 0 0" xyz="1 0 0"/>
      <geometry>
        <box size="2. 0.1 0.1"/>
      </geometry>
    </collision>
  </link>
  <joint name="stick_B_to_stick_C" type="continuous">
    <axis xyz="0 0 1"/>
    <parent link="stick_B"/>
    <child link="stick_C"/>
    <origin rpy="0 0 0" xyz="2 0 0"/>
  </joint>
  <link name="stick_D">
    <visual>
      <origin rpy="0 0 0" xyz="1 0 0"/>
      <geometry>
        <box size="2.0 0.1 0.1"/>
      </geometry>
    </visual>
    <collision>
      <origin rpy="0 0 0" xyz="1 0 0"/>
      <geometry>
        <box size="2. 0.1 0.1"/>
      </geometry>
    </collision>
  </link>
  <joint name="stick_C_to_stick_D" type="continuous">
    <axis xyz="0 0 1"/>
    <parent link="stick_C"/>
    <child link="stick_D"/>
    <origin rpy="0 0 0" xyz="2 0 0"/>
  </joint>
</robot>

