<?xml version="1.0" ?>
<!-- =================================================================================== -->
<!-- |    This document was autogenerated by xacro from src/four_linkage_demo/demo_common/demo_description/robots/demo_model.urdf.xacro | -->
<!-- |    EDITING THIS FILE BY HAND IS NOT RECOMMENDED                                 | -->
<!-- =================================================================================== -->
<robot name="demo_model">
  <link name="base_link"/>
  <link name="link_A">
    <visual>
      <origin rpy="0 0 0" xyz="1 0 0"/>
      <geometry>
        <box size="2.0 0.1 0.1"/>
      </geometry>
    </visual>
    <collision>
      <origin rpy="0 0 0" xyz="1 0 0"/>
      <geometry>
        <box size="2. 0.1 0.1"/>
      </geometry>
    </collision>
  </link>
  <link name="link_B">
    <visual>
      <origin rpy="0 0 0" xyz="1 0 0"/>
      <geometry>
        <box size="2.0 0.1 0.1"/>
      </geometry>
    </visual>
    <collision>
      <origin rpy="0 0 0" xyz="1 0 0"/>
      <geometry>
        <box size="2. 0.1 0.1"/>
      </geometry>
    </collision>
  </link>
  <link name="link_C">
    <visual>
      <origin rpy="0 0 0" xyz="1 0 0"/>
      <geometry>
        <box size="2.0 0.1 0.1"/>
      </geometry>
    </visual>
    <collision>
      <origin rpy="0 0 0" xyz="1 0 0"/>
      <geometry>
        <box size="2. 0.1 0.1"/>
      </geometry>
    </collision>
  </link>
  <link name="link_D">
    <visual>
      <origin rpy="0 0 0" xyz="1 0 0"/>
      <geometry>
        <box size="2.0 0.1 0.1"/>
      </geometry>
    </visual>
    <collision>
      <origin rpy="0 0 0" xyz="1 0 0"/>
      <geometry>
        <box size="2. 0.1 0.1"/>
      </geometry>
    </collision>
  </link>
  <joint name="base_link_to_link_A" type="fixed">
    <parent link="base_link"/>
    <child link="link_A"/>
    <origin rpy="0 0 0.785398185" xyz="0 0 0"/>
  </joint>
  <joint name="link_A_to_link_B" type="revolute">
    <axis xyz="0 0 1"/>
    <limit effort="100.0" lower="-0.785398185" upper="0.785398185" velocity="3.14159274"/>
    <dynamics damping="0.1"/>
    <parent link="link_A"/>
    <child link="link_B"/>
    <origin rpy="0 0 -1.57079637" xyz="2 0 0"/>
  </joint>
  <transmission name="link_A_to_link_B_trans">
    <type>transmission_interface/SimpleTransmission</type>
    <joint name="link_A_to_link_B">
      <hardwareInterface>hardware_interface/EffortJointInterface</hardwareInterface>
    </joint>
    <actuator name="link_A_to_link_B_motor">
      <hardwareInterface>hardware_interface/EffortJointInterface</hardwareInterface>
      <mechanicalReduction>1</mechanicalReduction>
    </actuator>
  </transmission>
  <joint name="link_B_to_link_C" type="continuous">
    <axis xyz="0 0 1"/>
    <parent link="link_B"/>
    <child link="link_C"/>
    <origin rpy="0 0 -1.57079637" xyz="2 0 0"/>
  </joint>
  <joint name="link_C_to_link_D" type="continuous">
    <axis xyz="0 0 1"/>
    <parent link="link_C"/>
    <child link="link_D"/>
    <origin rpy="0 0 -1.57079637" xyz="2 0 0"/>
  </joint>
</robot>

